{
    "registryname": "infernal_deconglomerator",
    "localizedname": "Infernal Deconglomerator",
	"requires-blueprint": true,
    "color": "333333",
    "parts": [
        {
            "x": -1,
            "y": 0,
            "z": 0,

            "elements": [
                "mekanism:basicblock@9"
            ]
        },
        {
            "x": 1,
            "y": 2,
            "z": 1,
            "elements": [
                "thaumcraft:slab_arcane_stone"
            ]
        },
        {
            "x": 1,
            "y": 0,
            "z": 0,

            "elements": [
                "mekanism:basicblock@9"
            ]
        },
        {
            "x": -2,
            "y": 0,
            "z": 0,

            "elements": [
                "mekanism:basicblock@9"
            ]
        },
        {
            "x": 2,
            "y": 2,
            "z": 1,
            "elements": [
                "thaumcraft:slab_arcane_stone"
            ]
        },
        {
            "x": 2,
            "y": 0,
            "z": 0,

            "elements": [
                "mekanism:basicblock@9"
            ]
        },
        {
            "x": -3,
            "y": 0,
            "z": 0,
            "elements": [
                "minecraft:nether_brick@0"
            ]
        },
        {
            "x": 3,
            "y": 2,
            "z": 1,

            "elements": [
                "mekanism:basicblock@9"
            ]
        },
        {
            "x": 3,
            "y": 0,
            "z": 0,
            "elements": [
                "minecraft:nether_brick@0"
            ]
        },
        {
            "x": 3,
            "y": -1,
            "z": 0,
            "elements": [
                "minecraft:nether_brick@0"
            ]
        },
        {
            "x": -3,
            "y": 1,
            "z": 0,
            "elements": [
                "minecraft:nether_brick@0"
            ]
        },
        {
            "x": 2,
            "y": -1,
            "z": 0,
            "elements": [
                "minecraft:nether_brick_fence@0"
            ]
        },
        {
            "x": -2,
            "y": 3,
            "z": 1,
            "elements": [
                "minecraft:stone_slab@6"
            ]
        },
        {
            "x": -2,
            "y": 1,
            "z": 0,

            "elements": [
                "mekanism:basicblock@10"
            ]
        },
        {
            "x": 1,
            "y": -1,
            "z": 0,
            "elements": [
                "minecraft:nether_brick_fence@0"
            ]
        },
        {
            "x": -1,
            "y": 3,
            "z": 1,
            "elements": [
                "minecraft:stone_slab@6"
            ]
        },
        {
            "x": -1,
            "y": 1,
            "z": 0,

            "elements": [
                "mekanism:basicblock@10"
            ]
        },
        {
            "x": 0,
            "y": -1,
            "z": 0,
            "elements": [
                "minecraft:nether_brick_fence@0"
            ]
        },
        {
            "x": 0,
            "y": 3,
            "z": 1,
            "elements": [
                "minecraft:stone_slab@6"
            ]
        },
        {
            "x": 0,
            "y": 1,
            "z": 0,

            "elements": [
                "mekanism:basicblock@10"
            ]
        },
        {
            "x": -1,
            "y": -1,
            "z": 0,
            "elements": [
                "minecraft:nether_brick_fence@0"
            ]
        },
        {
            "x": 1,
            "y": 3,
            "z": 1,
            "elements": [
                "minecraft:stone_slab@6"
            ]
        },
        {
            "x": 1,
            "y": 1,
            "z": 0,

            "elements": [
                "mekanism:basicblock@10"
            ]
        },
        {
            "x": -2,
            "y": -1,
            "z": 0,
            "elements": [
                "minecraft:nether_brick_fence@0"
            ]
        },
        {
            "x": 2,
            "y": 3,
            "z": 1,
            "elements": [
                "minecraft:stone_slab@6"
            ]
        },
        {
            "x": 2,
            "y": 1,
            "z": 0,

            "elements": [
                "mekanism:basicblock@10"
            ]
        },
        {
            "x": -3,
            "y": -1,
            "z": 0,
            "elements": [
                "minecraft:nether_brick@0"
            ]
        },
        {
            "x": -3,
            "y": -1,
            "z": 3,
            "elements": [
                "minecraft:nether_brick@0"
            ]
        },
        {
            "x": 3,
            "y": 1,
            "z": 0,
            "elements": [
                "minecraft:nether_brick@0"
            ]
        },
        {
            "x": -2,
            "y": -1,
            "z": 3,
            "elements": [
                "minecraft:nether_brick_fence@0"
            ]
        },
        {
            "x": -1,
            "y": -1,
            "z": 3,
            "elements": [
                "minecraft:nether_brick_fence@0"
            ]
        },
        {
            "x": 0,
            "y": -1,
            "z": 3,
            "elements": [
                "minecraft:nether_brick_fence@0"
            ]
        },
        {
            "x": 1,
            "y": -1,
            "z": 3,
            "elements": [
                "minecraft:nether_brick_fence@0"
            ]
        },
        {
            "x": 2,
            "y": -1,
            "z": 3,
            "elements": [
                "minecraft:nether_brick_fence@0"
            ]
        },
        {
            "x": 3,
            "y": -1,
            "z": 3,
            "elements": [
                "minecraft:nether_brick@0"
            ]
        },
        {
            "x": -3,
            "y": 2,
            "z": 0,
            "elements": [
                "minecraft:nether_brick@0"
            ]
        },
        {
            "x": -2,
            "y": 2,
            "z": 0,

            "elements": [
                "mekanism:basicblock@9"
            ]
        },
        {
            "x": -1,
            "y": 2,
            "z": 0,

            "elements": [
                "mekanism:basicblock@9"
            ]
        },
        {
            "x": 0,
            "y": 2,
            "z": 0,

            "elements": [
                "mekanism:basicblock@9"
            ]
        },
        {
            "x": 1,
            "y": 2,
            "z": 0,

            "elements": [
                "mekanism:basicblock@9"
            ]
        },
        {
            "x": 2,
            "y": 2,
            "z": 0,

            "elements": [
                "mekanism:basicblock@9"
            ]
        },
        {
            "x": -3,
            "y": 0,
            "z": 3,
            "elements": [
                "minecraft:nether_brick@0"
            ]
        },
        {
            "x": 3,
            "y": 2,
            "z": 0,
            "elements": [
                "minecraft:nether_brick@0"
            ]
        },
        {
            "x": -2,
            "y": 0,
            "z": 3,

            "elements": [
                "mekanism:basicblock@9"
            ]
        },
        {
            "x": -1,
            "y": 0,
            "z": 3,

            "elements": [
                "mekanism:basicblock@9"
            ]
        },
        {
            "x": 0,
            "y": 0,
            "z": 3,
            "elements": [
                "modulardiversity:blockmanainputhatch@0"
            ]
        },
        {
            "x": 1,
            "y": 0,
            "z": 3,

            "elements": [
                "mekanism:basicblock@9"
            ]
        },
        {
            "x": 2,
            "y": 0,
            "z": 3,

            "elements": [
                "mekanism:basicblock@9"
            ]
        },
        {
            "x": 3,
            "y": 0,
            "z": 3,
            "elements": [
                "minecraft:nether_brick@0"
            ]
        },
        {
            "x": -3,
            "y": 1,
            "z": 3,
            "elements": [
                "minecraft:nether_brick@0"
            ]
        },
        {
            "x": -3,
            "y": -1,
            "z": 2,
            "elements": [
                "minecraft:nether_brick_fence@0"
            ]
        },
        {
            "x": -2,
            "y": 1,
            "z": 3,

            "elements": [
                "mekanism:basicblock@10"
            ]
        },
        {
            "x": -2,
            "y": -1,
            "z": 2,

            "elements": [
                "mekanism:basicblock@9"
            ]
        },
        {
            "x": -1,
            "y": 1,
            "z": 3,

            "elements": [
                "mekanism:basicblock@10"
            ]
        },
        {
            "x": -1,
            "y": -1,
            "z": 2,

            "elements": [
                "mekanism:basicblock@9"
            ]
        },
        {
            "x": 0,
            "y": 1,
            "z": 3,

            "elements": [
                "mekanism:basicblock@10"
            ]
        },
        {
            "x": 0,
            "y": -1,
            "z": 2,

            "elements": [
                "mekanism:basicblock@9"
            ]
        },
        {
            "x": 1,
            "y": 1,
            "z": 3,

            "elements": [
                "mekanism:basicblock@10"
            ]
        },
        {
            "x": 1,
            "y": -1,
            "z": 2,

            "elements": [
                "mekanism:basicblock@9"
            ]
        },
        {
            "x": 2,
            "y": 1,
            "z": 3,

            "elements": [
                "mekanism:basicblock@10"
            ]
        },
        {
            "x": 2,
            "y": -1,
            "z": 2,

            "elements": [
                "mekanism:basicblock@9"
            ]
        },
        {
            "x": 3,
            "y": 1,
            "z": 3,
            "elements": [
                "minecraft:nether_brick@0"
            ]
        },
        {
            "x": 3,
            "y": -1,
            "z": 2,
            "elements": [
                "minecraft:nether_brick_fence@0"
            ]
        },
        {
            "x": -3,
            "y": 2,
            "z": 3,
            "elements": [
                "minecraft:nether_brick@0"
            ]
        },
        {
            "x": -2,
            "y": 2,
            "z": 3,

            "elements": [
                "mekanism:basicblock@9"
            ]
        },
        {
            "x": -3,
            "y": 0,
            "z": 2,
            "elements": [
                "modularmachinery:blockenergyinputhatch@0"
            ]
        },
        {
            "x": -2,
            "y": 0,
            "z": 2,
            "elements": [
                "minecraft:lava@0"
            ]
        },
        {
            "x": -1,
            "y": 2,
            "z": 3,

            "elements": [
                "mekanism:basicblock@9"
            ]
        },
        {
            "x": -1,
            "y": 0,
            "z": 2,
            "elements": [
                "minecraft:lava@0"
            ]
        },
        {
            "x": 0,
            "y": 2,
            "z": 3,

            "elements": [
                "mekanism:basicblock@9"
            ]
        },
        {
            "x": 0,
            "y": 0,
            "z": 2,
            "elements": [
                "minecraft:lava@0"
            ]
        },
        {
            "x": 1,
            "y": 2,
            "z": 3,

            "elements": [
                "mekanism:basicblock@9"
            ]
        },
        {
            "x": 1,
            "y": 0,
            "z": 2,
            "elements": [
                "minecraft:lava@0"
            ]
        },
        {
            "x": 2,
            "y": 2,
            "z": 3,

            "elements": [
                "mekanism:basicblock@9"
            ]
        },
        {
            "x": 2,
            "y": 0,
            "z": 2,
            "elements": [
                "minecraft:lava@0"
            ]
        },
        {
            "x": 3,
            "y": 2,
            "z": 3,
            "elements": [
                "minecraft:nether_brick@0"
            ]
        },
        {
            "x": 3,
            "y": 0,
            "z": 2,
            "elements": [
                "modularmachinery:blockfluidoutputhatch"
            ]
        },
        {
            "x": -3,
            "y": 1,
            "z": 2,

            "elements": [
                "mekanism:basicblock@10"
            ]
        },
        {
            "x": -3,
            "y": -1,
            "z": 1,
            "elements": [
                "minecraft:nether_brick_fence@0"
            ]
        },
        {
            "x": -2,
            "y": -1,
            "z": 1,

            "elements": [
                "mekanism:basicblock@9"
            ]
        },
        {
            "x": -1,
            "y": -1,
            "z": 1,

            "elements": [
                "mekanism:basicblock@9"
            ]
        },
        {
            "x": 0,
            "y": -1,
            "z": 1,

            "elements": [
                "mekanism:basicblock@9"
            ]
        },
        {
            "x": 1,
            "y": -1,
            "z": 1,

            "elements": [
                "mekanism:basicblock@9"
            ]
        },
        {
            "x": 2,
            "y": -1,
            "z": 1,

            "elements": [
                "mekanism:basicblock@9"
            ]
        },
        {
            "x": 3,
            "y": 1,
            "z": 2,

            "elements": [
                "mekanism:basicblock@10"
            ]
        },
        {
            "x": 3,
            "y": -1,
            "z": 1,
            "elements": [
                "minecraft:nether_brick_fence@0"
            ]
        },
        {
            "x": -3,
            "y": 2,
            "z": 2,
            "elements": [
                "mekanism:basicblock@9"
            ]
        },
        {
            "x": -2,
            "y": 2,
            "z": 2,
            "elements": [
                "thaumcraft:slab_arcane_stone"
            ]
        },
        {
            "x": -3,
            "y": 0,
            "z": 1,
            "elements": [
                "modularmachinery:blockinputbus"
            ]
        },
        {
            "x": -2,
            "y": 0,
            "z": 1,
            "elements": [
                "minecraft:lava@0"
            ]
        },
        {
            "x": -1,
            "y": 2,
            "z": 2,
            "elements": [
                "thaumcraft:slab_arcane_stone"
            ]
        },
        {
            "x": -1,
            "y": 0,
            "z": 1,
            "elements": [
                "minecraft:lava@0"
            ]
        },
        {
            "x": 0,
            "y": 2,
            "z": 2,
            "elements": [
                "thaumcraft:slab_arcane_stone"
            ]
        },
        {
            "x": 0,
            "y": 0,
            "z": 1,
            "elements": [
                "minecraft:lava@0"
            ]
        },
        {
            "x": 1,
            "y": 2,
            "z": 2,
            "elements": [
                "thaumcraft:slab_arcane_stone"
            ]
        },
        {
            "x": 1,
            "y": 0,
            "z": 1,
            "elements": [
                "minecraft:lava@0"
            ]
        },
        {
            "x": 2,
            "y": 2,
            "z": 2,
            "elements": [
                "thaumcraft:slab_arcane_stone"
            ]
        },
        {
            "x": 2,
            "y": 0,
            "z": 1,
            "elements": [
                "minecraft:lava@0"
            ]
        },
        {
            "x": 3,
            "y": 2,
            "z": 2,

            "elements": [
                "mekanism:basicblock@9"
            ]
        },
        {
            "x": 3,
            "y": 0,
            "z": 1,
            "elements": [
                "modularmachinery:blockoutputbus"
            ]
        },
        {
            "x": -2,
            "y": 3,
            "z": 2,
            "elements": [
                "minecraft:stone_slab@6"
            ]
        },
        {
            "x": -3,
            "y": 1,
            "z": 1,

            "elements": [
                "mekanism:basicblock@10"
            ]
        },
        {
            "x": -1,
            "y": 3,
            "z": 2,
            "elements": [
                "minecraft:stone_slab@6"
            ]
        },
        {
            "x": 0,
            "y": 3,
            "z": 2,
            "elements": [
                "minecraft:stone_slab@6"
            ]
        },
        {
            "x": 1,
            "y": 3,
            "z": 2,
            "elements": [
                "minecraft:stone_slab@6"
            ]
        },
        {
            "x": 2,
            "y": 3,
            "z": 2,
            "elements": [
                "minecraft:stone_slab@6"
            ]
        },
        {
            "x": 3,
            "y": 1,
            "z": 1,

            "elements": [
                "mekanism:basicblock@10"
            ]
        },
        {
            "x": -3,
            "y": 2,
            "z": 1,
            "elements": [
                "mekanism:basicblock@9"
            ]
        },
        {
            "x": -2,
            "y": 2,
            "z": 1,
            "elements": [
                "thaumcraft:slab_arcane_stone"
            ]
        },
        {
            "x": -1,
            "y": 2,
            "z": 1,
            "elements": [
                "thaumcraft:slab_arcane_stone"
            ]
        },
        {
            "x": 0,
            "y": 2,
            "z": 1,
            "elements": [
                "thaumcraft:slab_arcane_stone"
            ]
        }
    ]}